Workbook

Sheet Sheet1
A1: id | B1: name | C1: des | D1: pic | E1: quality | F1: type | G1: use_type | H1: sub_value | I1: limit_lv | J1: limit_time | K1: sell | L1: sort_priority | M1: jiage | N1: item_from | O1: item_source | P1: script | Q1: use_jump
A2: all | B2: all | C2: all | D2: all | E2: all | F2: all | G2: all | H2: all | I2: all | J2: all | K2: all | L2: all | M2: all | N2: all | O2: all | P2: all | Q2: all
A3: id | B3: 名称 | C3: 描述 | D3: 图标 | E3: 品质 | F3: 物品类型 | G3: 使用类型 | H3: 额外效果配置 | I3: 使用等级限制 | J3: 时间限制 | K3: 是否可出售 | L3: 排序权重 | M3: 售价 金币 | N3: 来源描述 | O3: 根据function_level表和200.lua | P3: 脚本 | Q3: 跳转
A4: int | B4: string | C4: string | D4: int | E4: int | F4: int | G4: int | H4: arrays | I4: int | J4: array | K4: int | L4: int | M4: int | N4: string | O4: string | P4: int | Q4: int
A5: 60000 | B5: 金币 | C5: 金币 | D5: 3006 | E5: 3 | F5: 13 | G5: 3 | H5: [60000,1] | I5: 1 | K5: 0 | L5: 1 | M5: 0 | P5: 0
A6: 60001 | B6: 元宝 | C6: 元宝 | D6: 3012 | E6: 3 | F6: 13 | G6: 3 | H6: [60001,1] | I6: 1 | K6: 0 | L6: 1 | M6: 0 | P6: 0
A7: 60006 | B7: 神将经验 | C7: 神将经验 | D7: 560 | E7: 3 | F7: 13 | G7: 3 | H7: [60006,1] | I7: 1 | K7: 0 | L7: 1 | M7: 0 | P7: 0
A8: 60014 | B8: 神魂 | C8: 神将魂魄 | D8: 3005 | E8: 4 | F8: 13 | G8: 3 | H8: [60014,1] | I8: 1 | K8: 0 | L8: 1 | M8: 0 | P8: 0
A9: 60015 | B9: 贵族经验 | C9: 贵族经验 | D9: 3011 | E9: 5 | F9: 13 | G9: 3 | H9: [60015,1] | I9: 1 | K9: 0 | L9: 1 | M9: 0 | P9: 0
A10: 60021 | B10: 帮贡 | C10: 帮派贡献度 | D10: 3026 | E10: 4 | F10: 13 | G10: 3 | H10: [60021,1] | I10: 1 | K10: 0 | L10: 1 | M10: 0 | P10: 0
A11: 60025 | B11: 星宿精华 | C11: 血战货币 | D11: 3019 | E11: 4 | F11: 13 | G11: 3 | H11: [60025,1] | I11: 1 | K11: 0 | L11: 1 | M11: 0 | P11: 0
A12: 60026 | B12: 体力 | C12: 体力 | D12: 3027 | E12: 3 | F12: 13 | G12: 3 | H12: [60026,1] | I12: 1 | K12: 0 | L12: 1 | M12: 0 | P12: 0
A13: 60050 | B13: 竞技场货币 | C13: 竞技场货币 | D13: 3022 | E13: 3 | F13: 13 | G13: 3 | H13: [60050,1] | I13: 1 | K13: 0 | L13: 1 | M13: 0 | P13: 0
A14: 60051 | B14: 昆仑币 | C14: 昆仑币 | D14: 3503 | E14: 4 | F14: 13 | G14: 3 | H14: [60051,1] | I14: 1 | K14: 0 | L14: 1 | M14: 0 | P14: 0
A15: 60052 | B15: 主角经验 | C15: 主角经验 | D15: 3007 | E15: 4 | F15: 13 | G15: 3 | H15: [60052,1] | I15: 1 | K15: 0 | L15: 1 | M15: 0 | P15: 0
A16: 60053 | B16: 法宝升级经验 | C16: 法宝升级经验 | D16: 3007 | E16: 4 | F16: 13 | G16: 3 | H16: [60053,1] | I16: 1 | K16: 0 | L16: 1 | M16: 0 | P16: 0
A17: 400 | B17: 刷新令 | D17: 5059 | E17: 4 | F17: 1 | G17: 0 | I17: 1 | K17: 0 | L17: 1 | M17: 0 | P17: 0
A18: 401 | B18: 竞技场挑战令 | D18: 5059 | E18: 4 | F18: 1 | G18: 2 | H18: [60027,5] | I18: 1 | K18: 0 | L18: 1 | M18: 0 | P18: 0
A19: 500 | B19: 体力丹 | C19: 使用增加25点体力 | D19: 5018 | E19: 4 | F19: 14 | G19: 2 | H19: [60026,25] | I19: 1 | K19: 0 | L19: 1 | M19: 0 | P19: 0
A20: 510 | B20: 蓝色装备盒 | C20: 打开有几率获得特级神将内丹、十连招募券、阵法书等神将相关稀有道具 | D20: 5001 | E20: 3 | F20: 5 | G20: 2 | I20: 1 | K20: 0 | L20: 410 | M20: 0 | N20: 来源：百花仙子、百花碎片合成 | O20: 8; | P20: 0
A21: 511 | B21: 紫色装备盒 | C21: 打开有几率获得神将天书、中级洗炼石、阵法书等稀有道具 | D21: 5000 | E21: 4 | F21: 5 | G21: 2 | I21: 1 | K21: 0 | L21: 410 | M21: 0 | N21: 来源：欢乐作战 | O21: 9; | P21: 0
A22: 512 | B22: 橙色装备盒 | C22: 打开有几率获中级洗炼石、幸运符和炼化石等装备锻造相关稀有道具 | D22: 5000 | E22: 5 | F22: 5 | G22: 2 | I22: 1 | K22: 0 | L22: 410 | M22: 0 | N22: 来源：挑战灵魔 | O22: 17; | P22: 0
A23: 513 | B23: 红色装备盒 | D23: 5000 | E23: 6 | F23: 5 | G23: 2 | I23: 1 | K23: 0 | L23: 410 | M23: 0 | N23: 来源：百花仙子、百花碎片合成 | O23: 8; | P23: 0
A24: 514 | B24: 金色装备盒 | D24: 5000 | E24: 7 | F24: 5 | G24: 2 | I24: 1 | K24: 0 | L24: 410 | M24: 0 | N24: 来源：欢乐作战 | O24: 9; | P24: 0
A25: 610 | B25: 初级精炼石 | C25: 装备洗炼属性时使用，用于重新生成装备的洗炼属性，只能洗出10星及以下的属性 | D25: 521 | E25: 2 | F25: 4 | G25: 0 | H25: [60017,10] | I25: 1 | K25: 0 | L25: 50 | M25: 10 | N25: 来源：商城、英勇试炼、锻造礼盒 | O25: 210;30;17 | P25: 0 | Q25: 1130
A26: 611 | B26: 中级精炼石 | C26: 用于装备洗炼时锁定某条属性，在下次洗炼操作中锁定的属性不会发生变化 | D26: 522 | E26: 3 | F26: 4 | G26: 0 | H26: [60017,20] | I26: 1 | K26: 0 | L26: 340 | M26: 20 | N26: 来源：商城、帮贡商城、英勇试炼、锻造礼盒 | O26: 210;125;30;17 | P26: 0 | Q26: 1130
A27: 612 | B27: 高级精炼石 | C27: 用于淬炼装备的辅助材料，配合炼化石可大幅度提升装备的淬炼属性 | D27: 523 | E27: 4 | F27: 4 | G27: 0 | H27: [60017,50] | I27: 1 | K27: 0 | L27: 40 | M27: 10 | N27: 来源：商城、淬炼副本、帮贡商城 | O27: 210;240-204;125 | P27: 0 | Q27: 1130
A28: 613 | B28: 特级精炼石 | C28: 蕴含远古神兽的血脉，是神将修炼天赋的一种必需材料 | D28: 524 | E28: 5 | F28: 4 | G28: 0 | H28: [60017,100] | I28: 1 | K28: 0 | L28: 140 | M28: 10 | N28: 来源：商城、帮贡商城、维护丹园、百花礼盒 | O28: 210;125;25;8 | P28: 0 | Q28: 1130
A29: 614 | B29: 法宝精华 | C29: 法宝修炼道具 | D29: 612 | E29: 5 | F29: 1 | G29: 0 | I29: 1 | K29: 0 | L29: 140 | M29: 10 | N29: 来源：商城、帮贡商城、维护丹园、百花礼盒 | O29: 210;125;25;8 | P29: 0
A30: 834 | B30: 初级神将内丹 | C30: 炼制的初级内丹，使用后可以提升200点神将经验 | D30: 3105 | E30: 2 | F30: 3 | G30: 0 | H30: [60006,200] | I30: 1 | K30: 0 | L30: 270 | M30: 100 | N30: 来源：副本-蓬莱仙山、杂货商城 | O30: 240;214 | P30: 0 | Q30: 1160
A31: 835 | B31: 中级神将内丹 | C31: 炼制的中级内丹，使用后可以提升500点神将经验 | D31: 3107 | E31: 3 | F31: 3 | G31: 0 | H31: [60006,500] | I31: 1 | K31: 0 | L31: 270 | M31: 250 | N31: 来源：副本-岱屿结界、副本-诛仙绝地、帮派种植、藏宝图、杂货商城 | O31: 240;28;29;214 | P31: 0 | Q31: 1160
A32: 836 | B32: 高级神将内丹 | C32: 炼制的高级内丹，使用后可以提升2500点神将经验 | D32: 3101 | E32: 4 | F32: 3 | G32: 0 | H32: [60006,2000] | I32: 1 | K32: 0 | L32: 270 | M32: 10000 | N32: 来源：商城、百花礼盒、欢乐礼盒 | O32: 210;8;9 | P32: 0 | Q32: 1160
A33: 837 | B33: 特级神将内丹 | C33: 炼制的特级内丹，使用后可以提升12500点神将经验 | D33: 3106 | E33: 5 | F33: 3 | G33: 0 | H33: [60006,10000] | I33: 1 | K33: 0 | L33: 270 | M33: 62500 | N33: 来源：百花礼盒、欢乐礼盒 | O33: 8;9 | P33: 0 | Q33: 1160
A34: 851 | B34: 突破丹 | C34: 神将突破消耗的道具 | D34: 612 | E34: 3 | F34: 1 | G34: 0 | I34: 1 | K34: 0 | L34: 20 | M34: 10 | N34: 来源：强化副本、商城 | O34: 240-202;210 | P34: 0 | Q34: 1180
A35: 852 | B35: 人参果 | C35: 神将培养消耗的道具 | D35: 5304 | E35: 4 | F35: 1 | G35: 0 | I35: 1 | K35: 0 | L35: 20 | M35: 30 | N35: 来源：六界使者、强化副本、、商城【背包-合成】 | O35: 33;240-202;210;112 | P35: 0
A36: 853 | B36: 修炼丹 | C36: 神将修炼消耗的物品 | D36: 5300 | E36: 5 | F36: 1 | G36: 0 | I36: 1 | K36: 0 | L36: 20 | M36: 90 | N36: 来源：商城、【背包-合成】 | O36: 210;112 | P36: 0
A37: 854 | B37: 觉醒石 | C37: 神将装备觉醒消耗的物品 | D37: 543 | E37: 6 | F37: 1 | G37: 0 | I37: 1 | K37: 0 | L37: 20 | M37: =M36*3 -> 270 | N37: 来源：商城、【背包-合成】 | O37: 210;112 | P37: 0 | Q37: 1140
A38: 855 | B38: 5级强化宝石 | C38: 强化等级16至19时使用，失败不降强化等级 | D38: 3018 | E38: 7 | F38: 1 | G38: 0 | I38: 1 | K38: 0 | L38: 20 | M38: 810 | N38: 来源：商城、【背包-合成】 | O38: 210;112 | P38: 0
A39: 1100 | B39: 百花礼盒 | C39: 打开有几率获得特级神将内丹、十连招募券、阵法书等神将相关稀有道具 | D39: 5001 | E39: 4 | F39: 5 | G39: 2 | I39: 1 | K39: 0 | L39: 410 | M39: 0 | N39: 来源：百花仙子、百花碎片合成 | O39: 8; | P39: 0
A40: 1101 | B40: 欢乐礼盒 | C40: 打开有几率获得神将天书、中级洗炼石、阵法书等稀有道具 | D40: 5000 | E40: 4 | F40: 5 | G40: 2 | I40: 1 | K40: 0 | L40: 410 | M40: 0 | N40: 来源：欢乐作战 | O40: 9; | P40: 0
...

Sheet Sheet2
A1: id | B1: name | C1: des | D1: pic | E1: type | F1: use_type | G1: dungeons_usetype | H1: sub_value | I1: superposition | J1: discard | K1: quality | L1: limit_lv | M1: sell | N1: price | O1: item_from | P1: item_source | Q1: item_into
A2: all | B2: all | C2: all | D2: all | E2: all | F2: all | G2: all | H2: all | I2: all | J2: all | K2: all | L2: all | M2: all | N2: all | O2: all | P2: all | Q2: all
A3: 道具ID | B3: 名称 | C3: 道具描述 | D3: 道具icon | E3: 类型 | F3: 使用类型 | G3: 副本中是否可使用 | H3: 额外效果配置 | I3: 叠加数量 | J3: 是否可丢弃 | K3: 品质 | L3: 使用等级限制 | M3: 是否可出售 | N3: 出售价格 | O3: 道具来源描述 | P3: 来源配置 | Q3: 使用跳转
A4: int | B4: string | C4: string | D4: int | E4: int | F4: int | G4: int | H4: array | I4: int | J4: int | K4: int | L4: int | M4: int | N4: array | O4: string | P4: array | Q4: array
D7: 7 | E7: 2401 | F7: 7
D8: 7 | E8: 2402 | F8: 7
D9: 7 | E9: 2403 | F9: 7
D10: 6 | E10: 2404 | F10: 6
D11: 6 | E11: 2405 | F11: 6
D12: 6 | E12: 2406 | F12: 6
D13: 5 | E13: 2407 | F13: 5
D14: 5 | E14: 2408 | F14: 5
D15: 5 | E15: 2409 | F15: 5
D16: 5 | E16: 2410 | F16: 5
D17: 5 | E17: 2426 | F17: 5
D18: 6 | E18: 2418 | F18: 6
... D54: 7 | E54: 2462 | F54: 7

Sheet Sheet3
